Workbook
Name Slicer_Loyality: #N/A
Name Slicer_Order_Date__Quarter: #N/A
Name Slicer_Order_Date__Year: #N/A
Name Slicer_Store_Type: #N/A

Sheet Customer_Dim
A1: Customer_ID | B1: Customer Name | C1: Age | D1: Gender | E1: City | F1: Loyality | G1: Age Category
A2: CUST1000 | B2: Sheena Bonilla | C2: 55 | D2: Male | E2: Donaldton | F2: Platinum | G2: =IF(C2>60,"Senior Citizen",IF(C2>40,"Middle age ",IF(C2>30,"Adults Age",IF(C2>20,"Young People","Teenage")))) -> Middle age
A3: CUST1001 | B3: Eugene Nelson | C3: 26 | D3: Female | E3: Phillipsmouth | F3: Platinum | G3: =IF(C3>60,"Senior Citizen",IF(C3>40,"Middle age ",IF(C3>30,"Adults Age",IF(C3>20,"Young People","Teenage")))) -> Young People
A4: CUST1002 | B4: Dr. Benjamin Price | C4: 29 | D4: Female | E4: Kylebury | F4: Platinum | G4: =IF(C4>60,"Senior Citizen",IF(C4>40,"Middle age ",IF(C4>30,"Adults Age",IF(C4>20,"Young People","Teenage")))) -> Young People
A5: CUST1003 | B5: Jeremy Harris | C5: 59 | D5: Female | E5: Thomastown | F5: Platinum | G5: =IF(C5>60,"Senior Citizen",IF(C5>40,"Middle age ",IF(C5>30,"Adults Age",IF(C5>20,"Young People","Teenage")))) -> Middle age
A6: CUST1004 | B6: Caroline Collins | C6: 64 | D6: Female | E6: Nicholasshire | F6: Bronze | G6: =IF(C6>60,"Senior Citizen",IF(C6>40,"Middle age ",IF(C6>30,"Adults Age",IF(C6>20,"Young People","Teenage")))) -> Senior Citizen
A7: CUST1005 | B7: Christine Vaughn | C7: 24 | D7: Male | E7: East Amandamouth | F7: Silver | G7: =IF(C7>60,"Senior Citizen",IF(C7>40,"Middle age ",IF(C7>30,"Adults Age",IF(C7>20,"Young People","Teenage")))) -> Young People
A8: CUST1006 | B8: Amber Jackson | C8: 29 | D8: Female | E8: Deborahborough | F8: Bronze | G8: =IF(C8>60,"Senior Citizen",IF(C8>40,"Middle age ",IF(C8>30,"Adults Age",IF(C8>20,"Young People","Teenage")))) -> Young People
A9: CUST1007 | B9: Daniel Boyd | C9: 29 | D9: Female | E9: West Pamelafurt | F9: Platinum | G9: =IF(C9>60,"Senior Citizen",IF(C9>40,"Middle age ",IF(C9>30,"Adults Age",IF(C9>20,"Young People","Teenage")))) -> Young People
A10: CUST1008 | B10: Melissa Howard | C10: 53 | D10: Female | E10: Maynardton | F10: Bronze | G10: =IF(C10>60,"Senior Citizen",IF(C10>40,"Middle age ",IF(C10>30,"Adults Age",IF(C10>20,"Young People","Teenage")))) -> Middle age
A11: CUST1009 | B11: Ms. Maria Leach | C11: 64 | D11: Male | E11: Melissashire | F11: Gold | G11: =IF(C11>60,"Senior Citizen",IF(C11>40,"Middle age ",IF(C11>30,"Adults Age",IF(C11>20,"Young People","Teenage")))) -> Senior Citizen
A12: CUST1010 | B12: Dominic Page | C12: 53 | D12: Male | E12: Port Michaelburgh | F12: Platinum | G12: =IF(C12>60,"Senior Citizen",IF(C12>40,"Middle age ",IF(C12>30,"Adults Age",IF(C12>20,"Young People","Teenage")))) -> Middle age
A13: CUST1011 | B13: Brian Lopez | C13: 28 | D13: Female | E13: East Krista | F13: Bronze | G13: =IF(C13>60,"Senior Citizen",IF(C13>40,"Middle age ",IF(C13>30,"Adults Age",IF(C13>20,"Young People","Teenage")))) -> Young People
... A501: CUST-1499 | B501: Philip Pennington | C501: 27 | D501: Female | E501: East Valerieview | F501: Silver | G501: =IF(C501>60,"Senior Citizen",IF(C501>40,"Middle age ",IF(C501>30,"Adults Age",IF(C501>20,"Young People","Teenage")))) -> Young People

Sheet Product_Dim
A1: Product_ID | B1: Product Name | C1: Category | D1: Brand | E1: Cost | F1: Stock
A2: PROD0 | B2: Brother Laser Printer | C2: Electronics | D2: Hunt Inc | E2: 112.42 | F2: 416
A3: PROD1 | B3: Men's Graphic T-Shirt | C3: Clothing | D3: Terry-Moore | E3: 342.56 | F3: 181
A4: PROD10 | B4: Ceramic Kitchen Bowl Set | C4: Home | D4: Hamilton Group | E4: 298.86 | F4: 308
A5: PROD11 | B5: HD Smart TV Stick | C5: Electronics | D5: Gibson, Hobbs and Weaver | E5: 449.4 | F5: Unknown
A6: PROD12 | B6: Hair Strengthening Shampoo | C6: Beauty | D6: Rice LLC | E6: 115.82 | F6: 460
A7: PROD13 | B7: USB-C Fast Charger | C7: Electronics | D7: Dawson-Perkins | E7: 242.23 | F7: 453
A8: PROD14 | B8: Decorative Wall Mirror | C8: Home | D8: Luna, Anderson and Bowman | E8: 48.01 | F8: 439
A9: PROD15 | B9: 4K Home Projector | C9: Electronics | D9: Thomas LLC | E9: 465.34 | F9: 301
A10: PROD16 | B10: Beard Grooming Kit | C10: Beauty | D10: Erickson-Green | E10: 337.42 | F10: 256
A11: PROD17 | B11: Soccer Training Cone Set | C11: Sports | D11: Ford, Murphy and Wilson | E11: 144.53 | F11: 367
A12: PROD18 | B12: Women's Denim Jeans | C12: Clothing | D12: Guerra-Hendrix | E12: 253.85131 | F12: 343
A13: PROD19 | B13: Knee Support Brace | C13: Sports | D13: May-Reese | E13: 21.34 | F13: 65
A14: PROD2 | B14: Women's Casual Hoodie | C14: Clothing | D14: Sims Inc | E14: 256.65265 | F14: 352
A15: PROD20 | B15: Outdoor Sports Water Bottle | C15: Sports | D15: Soto-Ellis | E15: 131.51 | F15: Unknown
A16: PROD21 | B16: Multi-Purpose Storage Box | C16: Home | D16: Gardner-Montes | E16: 123.46 | F16: 76
A17: PROD22 | B17: Carbon Fiber Tennis Racket | C17: Sports | D17: Flores, Pineda and Rodriguez | E17: 484.62 | F17: 432
A18: PROD23 | B18: Men's Formal Shirt | C18: Clothing | D18: Moon, Mora and Santos | E18: 257.03225 | F18: 360
A19: PROD24 | B19: Foldable Camping Chair | C19: Sports | D19: Cook Ltd | E19: 166.06 | F19: 340
A20: PROD25 | B20: Women's Scarf Set | C20: Clothing | D20: Brown and Sons | E20: 174.02 | F20: 268
A21: PROD26 | B21: Wireless Bluetooth Speaker | C21: Electronics | D21: Reed-Schmidt | E21: 322.41 | F21: 213
A22: PROD27 | B22: Decorative Floor Vase | C22: Home | D22: Khan, Jones and Paul | E22: 258.44273 | F22: 378
A23: PROD28 | B23: Sports Stopwatch Timer | C23: Sports | D23: Burns-Hansen | E23: 38.76 | F23: 137
A24: PROD29 | B24: Fabric Sofa Throw Blanket | C24: Home | D24: Hoffman Group | E24: 218.48 | F24: 276
A25: PROD3 | B25: Men's Running Jacket | C25: Clothing | D25: Pineda Ltd | E25: 364.67 | F25: 452
A26: PROD30 | B26: Stainless Steel Cutlery Set | C26: Home | D26: Stevens, Fernandez and Martin | E26: 19.52 | F26: 57
A27: PROD31 | B27: Basketball | C27: Sports | D27: Nolan-Snow | E27: 204.39 | F27: 281
... A52: PROD54 | B52: Sports Stopwatch Pro | C52: Sports | D52: Thompson-French | E52: 434.84 | F52: 185
A53: PROD55 | B53: Ceramic Plant Pot | C53: Home | D53: Hatfield, Baird and Torres | E53: 81.75 | F53: Unknown
A54: PROD56 | B54: Premium Blanket Throw | C54: Home | D54: Hernandez, Kennedy and Porter | E54: 461.47 | F54: 190
A55: PROD57 | B55: Foam Roller | C55: Sports | D55: Atkinson, Camacho and Oliver | E55: 30.62 | F55: 138
A56: PROD58 | B56: Womens Cotton Scarf | C56: Clothing | D56: Shepherd-Gould | E56: 113.83 | F56: 485
A57: PROD59 | B57: Men's Hair Styling Gel | C57: Beauty | D57: Cline-Mccarthy | E57: 17.31 | F57: 399
A58: PROD6 | B58: Herbal Face Moisturizer | C58: Beauty | D58: Davidson PLC | E58: 312.8 | F58: 350
A59: PROD60 | B59: Luxury Perfume Spray | C59: Beauty | D59: Gibson, Green and Lopez | E59: 482.75 | F59: 444
A60: PROD61 | B60: Tennis Ball 3-Pack | C60: Sports | D60: Lopez LLC | E60: 103.45 | F60: 465
A61: PROD62 | B61: Laptop Cooling Pad | C61: Electronics | D61: Murray, Gould and Ware | E61: 86.42 | F61: 222
A62: PROD63 | B62: Organic Sunscreen Lotion | C62: Beauty | D62: Anderson-Riley | E62: 266.86 | F62: 458
A63: PROD64 | B63: Matte Lipstick Set | C63: Beauty | D63: Zhang Inc | E63: 299.11 | F63: 118
A64: PROD65 | B64: Adjustable Dumbbells 20kg | C64: Sports | D64: Montgomery, Benton and Miller | E64: 240.63 | F64: 423
...

Sheet Store_Dim
A1: Store_ID | B1: Store_Name | C1: Region | D1: City | E1: Store_Type
A2: STORE0 | B2: Rivera-Warner | C2: East | D2: Washingtonfurt | E2: Flagship
A3: STORE1 | B3: Martinez, Adkins and Johnson | C3: North | D3: Danielmouth | E3: Flagship
A4: STORE10 | B4: Hill, Wagner and Ballard | C4: East | D4: East Davidville | E4: Online
A5: STORE11 | B5: Aguirre-Keller | C5: South | D5: Lake Michael | E5: Online
A6: STORE12 | B6: Thomas, Bridges and Harris | C6: North | D6: Sabrinatown | E6: Online
A7: STORE13 | B7: Gardner, Humphrey and Contreras | C7: East | D7: Johnsonville | E7: Flagship
A8: STORE14 | B8: Mcdonald Inc | C8: South | D8: Christopherland | E8: Outlet
A9: STORE15 | B9: Shelton PLC | C9: North | D9: East Jenniferstad | E9: Flagship | M9: f
A10: STORE16 | B10: Frederick-Wright | C10: West | D10: New Jimmymouth | E10: Flagship
A11: STORE17 | B11: Holloway Ltd | C11: North | D11: Bensonhaven | E11: Flagship
A12: STORE18 | B12: Guerrero-Schmitt | C12: East | D12: East Stevechester | E12: Flagship
A13: STORE19 | B13: Mann-Austin | C13: East | D13: Vasquezborough | E13: Online
A14: STORE2 | B14: Black-Horn | C14: South | D14: North Nancyview | E14: Outlet
A15: STORE3 | B15: Johnson-Wright | C15: North | D15: Hoodberg | E15: Outlet
A16: STORE4 | B16: Alexander Group | C16: South | D16: Port Sharon | E16: Online
A17: STORE5 | B17: Gray Ltd | C17: North | D17: New Michaelchester | E17: Outlet
A18: STORE6 | B18: Benson-Elliott | C18: East | D18: Port Josephberg | E18: Online
A19: STORE7 | B19: Martinez-Mullins | C19: South | D19: Williamsfurt | E19: Online
A20: STORE8 | B20: Bean, Jones and Park | C20: West | D20: Thompsonborough | E20: Online
A21: STORE9 | B21: Moore, Padilla and Butler | C21: South | D21: East Johnstad | E21: Flagship

Sheet sales_data
A1: SALE_ID | B1: Order_Date | C1: Customer_Id | D1: Product Id | E1: Store_ID | F1: Quantity | G1: Unit_Price | H1: Discount | I1: Payment Method | J1: Total Price
A2: SALE0 | B2: 45480 | C2: CUST1409 | D2: PROD97 | E2: STORE3 | F2: 1 | G2: 218.04 | H2: 0.09 | I2: Credit Card | J2: =sale_tab6[[#This Row],[Quantity]]*sale_tab6[[#This Row],[Unit_Price]]*(1-sale_tab6[[#This Row],[Discount]]) -> 198.4164
A3: SALE1 | B3: 45285 | C3: CUST1467 | D3: PROD74 | E3: STORE17 | F3: 3 | G3: 104.47 | H3: 0.27 | I3: PayPal | J3: =sale_tab6[[#This Row],[Quantity]]*sale_tab6[[#This Row],[Unit_Price]]*(1-sale_tab6[[#This Row],[Discount]]) -> 228.7893
A4: SALE10 | B4: 45335 | C4: CUST1065 | D4: PROD24 | E4: STORE14 | F4: 1 | G4: 278.63 | H4: 0.07 | I4: Credit Card | J4: =sale_tab6[[#This Row],[Quantity]]*sale_tab6[[#This Row],[Unit_Price]]*(1-sale_tab6[[#This Row],[Discount]]) -> 259.1259
A5: SALE100 | B5: 45677 | C5: CUST1369 | D5: PROD33 | E5: STORE5 | F5: 2 | G5: 401.5 | H5: 0.18 | I5: Credit Card | J5: =sale_tab6[[#This Row],[Quantity]]*sale_tab6[[#This Row],[Unit_Price]]*(1-sale_tab6[[#This Row],[Discount]]) -> 658.46
A6: SALE1000 | B6: 45456 | C6: CUST1190 | D6: PROD59 | E6: STORE2 | F6: 2 | G6: 909.51 | H6: 0.27 | I6: Credit Card | J6: =sale_tab6[[#This Row],[Quantity]]*sale_tab6[[#This Row],[Unit_Price]]*(1-sale_tab6[[#This Row],[Discount]]) -> 1327.8846
A7: SALE1001 | B7: 45776 | C7: CUST1052 | D7: PROD69 | E7: STORE14 | F7: 4 | G7: 593.84 | H7: 0.24 | I7: PayPal | J7: =sale_tab6[[#This Row],[Quantity]]*sale_tab6[[#This Row],[Unit_Price]]*(1-sale_tab6[[#This Row],[Discount]]) -> 1805.2736
A8: SALE1002 | B8: 45566 | C8: CUST1109 | D8: PROD73 | E8: STORE10 | F8: 3 | G8: 909.11 | H8: 0.23 | I8: COD | J8: =sale_tab6[[#This Row],[Quantity]]*sale_tab6[[#This Row],[Unit_Price]]*(1-sale_tab6[[#This Row],[Discount]]) -> 2100.0441
A9: SALE1003 | B9: 45542 | C9: CUST1399 | D9: PROD24 | E9: STORE1 | F9: 4 | G9: 996.85 | H9: 0.24 | I9: PayPal | J9: =sale_tab6[[#This Row],[Quantity]]*sale_tab6[[#This Row],[Unit_Price]]*(1-sale_tab6[[#This Row],[Discount]]) -> 3030.424
A10: SALE1004 | B10: 45834 | C10: CUST1300 | D10: PROD0 | E10: STORE17 | F10: 1 | G10: 522.69 | H10: 0.06 | I10: COD | J10: =sale_tab6[[#This Row],[Quantity]]*sale_tab6[[#This Row],[Unit_Price]]*(1-sale_tab6[[#This Row],[Discount]]) -> 491.3286
A11: SALE1005 | B11: 45405 | C11: CUST1194 | D11: PROD54 | E11: STORE3 | F11: 3 | G11: 261.05 | H11: 0.12 | I11: PayPal | J11: =sale_tab6[[#This Row],[Quantity]]*sale_tab6[[#This Row],[Unit_Price]]*(1-sale_tab6[[#This Row],[Discount]]) -> 689.172
A12: SALE1006 | B12: 45918 | C12: CUST1087 | D12: PROD23 | E12: STORE17 | F12: 3 | G12: 644.73 | H12: 0.01 | I12: COD | J12: =sale_tab6[[#This Row],[Quantity]]*sale_tab6[[#This Row],[Unit_Price]]*(1-sale_tab6[[#This Row],[Discount]]) -> 1914.8481
A13: SALE1007 | B13: 45217 | C13: CUST1198 | D13: PROD75 | E13: STORE2 | F13: 2 | G13: 541.52 | H13: 0.26 | I13: PayPal | J13: =sale_tab6[[#This Row],[Quantity]]*sale_tab6[[#This Row],[Unit_Price]]*(1-sale_tab6[[#This Row],[Discount]]) -> 801.4496
... A1179: SALE258 | B1179: 45300 | C1179: CUST1136 | D1179: PROD35 | E1179: STORE17 | F1179: 1 | G1179: 222.94 | H1179: 0.19 | I1179: Credit Card | J1179: =sale_tab6[[#This Row],[Quantity]]*sale_tab6[[#This Row],[Unit_Price]]*(1-sale_tab6[[#This Row],[Discount]]) -> 180.5814
A1180: SALE259 | B1180: 45773 | C1180: CUST1248 | D1180: PROD35 | E1180: STORE2 | F1180: 2 | G1180: 355.3 | I1180: PayPal | J1180: =sale_tab6[[#This Row],[Quantity]]*sale_tab6[[#This Row],[Unit_Price]]*(1-sale_tab6[[#This Row],[Discount]]) -> 710.6
A1181: SALE26 | B1181: 45294 | C1181: CUST1213 | D1181: PROD98 | E1181: STORE8 | F1181: 4 | G1181: 156.16 | I1181: Credit Card | J1181: =sale_tab6[[#This Row],[Quantity]]*sale_tab6[[#This Row],[Unit_Price]]*(1-sale_tab6[[#This Row],[Discount]]) -> 624.64
A1182: SALE260 | B1182: 45497 | C1182: CUST1103 | D1182: PROD89 | E1182: STORE19 | F1182: 4 | G1182: 611.3 | H1182: 0.11 | I1182: PayPal | J1182: =sale_tab6[[#This Row],[Quantity]]*sale_tab6[[#This Row],[Unit_Price]]*(1-sale_tab6[[#This Row],[Discount]]) -> 2176.228
A1183: SALE261 | B1183: 45742 | C1183: CUST1333 | D1183: PROD0 | E1183: STORE8 | F1183: 4 | G1183: 849.21 | H1183: 0.07 | I1183: Credit Card | J1183: =sale_tab6[[#This Row],[Quantity]]*sale_tab6[[#This Row],[Unit_Price]]*(1-sale_tab6[[#This Row],[Discount]]) -> 3159.0612
A1184: SALE262 | B1184: 45713 | C1184: CUST1209 | D1184: PROD42 | E1184: STORE7 | F1184: 3 | G1184: 553.12 | H1184: 0.28 | I1184: COD | J1184: =sale_tab6[[#This Row],[Quantity]]*sale_tab6[[#This Row],[Unit_Price]]*(1-sale_tab6[[#This Row],[Discount]]) -> 1194.7392
A1185: SALE263 | B1185: 45826 | C1185: CUST1282 | D1185: PROD91 | E1185: STORE9 | F1185: 2 | G1185: 903.08 | H1185: 0.18 | I1185: COD | J1185: =sale_tab6[[#This Row],[Quantity]]*sale_tab6[[#This Row],[Unit_Price]]*(1-sale_tab6[[#This Row],[Discount]]) -> 1481.0512
A1186: SALE264 | B1186: 45648 | C1186: CUST1478 | D1186: PROD16 | E1186: STORE11 | F1186: 4 | G1186: 640.23 | H1186: 0.06 | I1186: COD | J1186: =sale_tab6[[#This Row],[Quantity]]*sale_tab6[[#This Row],[Unit_Price]]*(1-sale_tab6[[#This Row],[Discount]]) -> 2407.2648
A1187: SALE265 | B1187: 45836 | C1187: CUST1141 | D1187: PROD21 | E1187: STORE6 | F1187: 1 | G1187: 518 | H1187: 0.25 | I1187: Credit Card | J1187: =sale_tab6[[#This Row],[Quantity]]*sale_tab6[[#This Row],[Unit_Price]]*(1-sale_tab6[[#This Row],[Discount]]) -> 388.5
A1188: SALE266 | B1188: 45437 | C1188: CUST1433 | D1188: PROD64 | E1188: STORE4 | F1188: 4 | G1188: 779.25 | H1188: 0.25 | I1188: Credit Card | J1188: =sale_tab6[[#This Row],[Quantity]]*sale_tab6[[#This Row],[Unit_Price]]*(1-sale_tab6[[#This Row],[Discount]]) -> 2337.75
A1189: SALE267 | B1189: 45807 | C1189: CUST1118 | D1189: PROD83 | E1189: STORE7 | F1189: 2 | G1189: 467.75 | H1189: 0.26 | I1189: Credit Card | J1189: =sale_tab6[[#This Row],[Quantity]]*sale_tab6[[#This Row],[Unit_Price]]*(1-sale_tab6[[#This Row],[Discount]]) -> 692.27
A1190: SALE268 | B1190: 45555 | C1190: CUST1406 | D1190: PROD90 | E1190: STORE18 | F1190: 3 | G1190: 514 | H1190: 0.06 | I1190: Credit Card | J1190: =sale_tab6[[#This Row],[Quantity]]*sale_tab6[[#This Row],[Unit_Price]]*(1-sale_tab6[[#This Row],[Discount]]) -> 1449.48
A1191: SALE269 | B1191: 45803 | C1191: CUST1219 | D1191: PROD37 | E1191: STORE0 | F1191: 4 | G1191: 747.01 | H1191: 0.13 | I1191: PayPal | J1191: =sale_tab6[[#This Row],[Quantity]]*sale_tab6[[#This Row],[Unit_Price]]*(1-sale_tab6[[#This Row],[Discount]]) -> 2599.5948
A1192: SALE27 | B1192: 45710 | C1192: CUST1200 | D1192: PROD77 | E1192: STORE8 | F1192: 3 | G1192: 815.49 | H1192: 0.17 | I1192: Credit Card | J1192: =sale_tab6[[#This Row],[Quantity]]*sale_tab6[[#This Row],[Unit_Price]]*(1-sale_tab6[[#This Row],[Discount]]) -> 2030.5701
A1193: SALE270 | B1193: 45735 | C1193: CUST1101 | D1193: PROD89 | E1193: STORE12 | F1193: 4 | G1193: 461.83 | H1193: 0.28 | I1193: PayPal | J1193: =sale_tab6[[#This Row],[Quantity]]*sale_tab6[[#This Row],[Unit_Price]]*(1-sale_tab6[[#This Row],[Discount]]) -> 1330.0704
... A1469: SALE519 | B1469: 45495 | C1469: CUST1233 | D1469: PROD88 | E1469: STORE0 | F1469: 4 | G1469: 370.09 | H1469: 0.22 | I1469: COD | J1469: =sale_tab6[[#This Row],[Quantity]]*sale_tab6[[#This Row],[Unit_Price]]*(1-sale_tab6[[#This Row],[Discount]]) -> 1154.6808
A1470: SALE52 | B1470: 45894 | C1470: CUST1148 | D1470: PROD89 | E1470: STORE6 | F1470: 3 | G1470: 514 | I1470: Credit Card | J1470: =sale_tab6[[#This Row],[Quantity]]*sale_tab6[[#This Row],[Unit_Price]]*(1-sale_tab6[[#This Row],[Discount]]) -> 1542
A1471: SALE520 | B1471: 45229 | C1471: CUST1253 | D1471: PROD78 | E1471: STORE6 | F1471: 3 | G1471: 679.22 | H1471: 0.11 | I1471: PayPal | J1471: =sale_tab6[[#This Row],[Quantity]]*sale_tab6[[#This Row],[Unit_Price]]*(1-sale_tab6[[#This Row],[Discount]]) -> 1813.5174
A1472: SALE521 | B1472: 45433 | C1472: CUST1373 | D1472: PROD73 | E1472: STORE0 | F1472: 3 | G1472: 780.69 | H1472: 0.1 | I1472: COD | J1472: =sale_tab6[[#This Row],[Quantity]]*sale_tab6[[#This Row],[Unit_Price]]*(1-sale_tab6[[#This Row],[Discount]]) -> 2107.863
A1473: SALE522 | B1473: 45766 | C1473: CUST1261 | D1473: PROD42 | E1473: STORE2 | F1473: 2 | G1473: 42.97 | H1473: 0.18 | I1473: PayPal | J1473: =sale_tab6[[#This Row],[Quantity]]*sale_tab6[[#This Row],[Unit_Price]]*(1-sale_tab6[[#This Row],[Discount]]) -> 70.4708
A1474: SALE523 | B1474: 45639 | C1474: CUST1286 | D1474: PROD82 | E1474: STORE0 | F1474: 4 | G1474: 854.37 | H1474: 0.07 | I1474: PayPal | J1474: =sale_tab6[[#This Row],[Quantity]]*sale_tab6[[#This Row],[Unit_Price]]*(1-sale_tab6[[#This Row],[Discount]]) -> 3178.2564
A1475: SALE524 | B1475: 45774 | C1475: CUST1100 | D1475: PROD24 | E1475: STORE16 | F1475: 2 | G1475: 409.52 | H1475: 0.06 | I1475: COD | J1475: =sale_tab6[[#This Row],[Quantity]]*sale_tab6[[#This Row],[Unit_Price]]*(1-sale_tab6[[#This Row],[Discount]]) -> 769.8976
A1476: SALE525 | B1476: 45569 | C1476: CUST1164 | D1476: PROD74 | E1476: STORE10 | F1476: 2 | G1476: 407.46 | H1476: 0.21 | I1476: Credit Card | J1476: =sale_tab6[[#This Row],[Quantity]]*sale_tab6[[#This Row],[Unit_Price]]*(1-sale_tab6[[#This Row],[Discount]]) -> 643.7868
A1477: SALE526 | B1477: 45856 | C1477: CUST1228 | D1477: PROD4 | E1477: STORE8 | F1477: 1 | G1477: 728.84 | H1477: 0.28 | I1477: PayPal | J1477: =sale_tab6[[#This Row],[Quantity]]*sale_tab6[[#This Row],[Unit_Price]]*(1-sale_tab6[[#This Row],[Discount]]) -> 524.7648
A1478: SALE527 | B1478: 45362 | C1478: CUST1453 | D1478: PROD78 | E1478: STORE6 | F1478: 4 | G1478: 467.24 | H1478: 0.08 | I1478: PayPal | J1478: =sale_tab6[[#This Row],[Quantity]]*sale_tab6[[#This Row],[Unit_Price]]*(1-sale_tab6[[#This Row],[Discount]]) -> 1719.4432
A1479: SALE528 | B1479: 45457 | C1479: CUST1092 | D1479: PROD10 | E1479: STORE11 | F1479: 1 | G1479: 57.94 | H1479: 0.13 | I1479: PayPal | J1479: =sale_tab6[[#This Row],[Quantity]]*sale_tab6[[#This Row],[Unit_Price]]*(1-sale_tab6[[#This Row],[Discount]]) -> 50.4078
A1480: SALE529 | B1480: 45338 | C1480: CUST1344 | D1480: PROD49 | E1480: STORE17 | F1480: 1 | G1480: 540.1 | H1480: 0.22 | I1480: Credit Card | J1480: =sale_tab6[[#This Row],[Quantity]]*sale_tab6[[#This Row],[Unit_Price]]*(1-sale_tab6[[#This Row],[Discount]]) -> 421.278
...

Sheet vlookup
A1: SALE_ID | B1: Order_Date | C1: Customer_Id | D1: Product Name | E1: Product Id | F1: Store_ID | G1: Quantity | H1: Unit_Price | I1: Discount | J1: Payment Method | K1: Total Price
A2: SALE0 | B2: 45480 | C2: CUST1409 | D2: =VLOOKUP(E2,Product_Dim!A:B,2,FALSE) -> Cricket Bat | E2: PROD97 | F2: STORE3 | G2: 1 | H2: 218.04 | I2: 0.09 | J2: Credit Card
A3: SALE1 | B3: 45285 | C3: CUST1467 | D3: =VLOOKUP(E3,Product_Dim!A:B,2,FALSE) -> Bluetooth Car Audio System | E3: PROD74 | F3: STORE17 | G3: 3 | H3: 104.47 | I3: 0.27 | J3: PayPal | K3: =sale_tab[[#This Row],[Quantity]]*sale_tab[[#This Row],[Unit_Price]]*(1-sale_tab[[#This Row],[Discount]]) -> 228.7893
A4: SALE2 | B4: 45446 | C4: CUST1056 | D4: =VLOOKUP(E4,Product_Dim!A:B,2,FALSE) -> Men's Roll-On Perfume | E4: PROD49 | F4: STORE8 | G4: 2.4799197 | H4: 914.05 | I4: 0.25 | J4: Credit Card | K4: =sale_tab[[#This Row],[Quantity]]*sale_tab[[#This Row],[Unit_Price]]*(1-sale_tab[[#This Row],[Discount]]) -> 1700.0779
A5: SALE3 | B5: 45259 | C5: CUST1346 | D5: =VLOOKUP(E5,Product_Dim!A:B,2,FALSE) -> Wireless Mouse | E5: PROD76 | F5: STORE8 | G5: 1 | H5: 921.51 | I5: 0.16 | J5: COD | K5: =sale_tab[[#This Row],[Quantity]]*sale_tab[[#This Row],[Unit_Price]]*(1-sale_tab[[#This Row],[Discount]]) -> 774.0684
A6: SALE4 | B6: 45297 | C6: CUST1493 | D6: =VLOOKUP(E6,Product_Dim!A:B,2,FALSE) -> Men's Hair Styling Gel | E6: PROD59 | F6: STORE5 | G6: 3 | H6: 745.3 | I6: 0.18 | J6: Credit Card | K6: =sale_tab[[#This Row],[Quantity]]*sale_tab[[#This Row],[Unit_Price]]*(1-sale_tab[[#This Row],[Discount]]) -> 1833.438
A7: SALE5 | B7: 45499 | C7: CUST1116 | D7: =VLOOKUP(E7,Product_Dim!A:B,2,FALSE) -> 4K Home Projector | E7: PROD15 | F7: STORE7 | G7: 3 | H7: 147.01 | I7: 0.19 | J7: COD | K7: =sale_tab[[#This Row],[Quantity]]*sale_tab[[#This Row],[Unit_Price]]*(1-sale_tab[[#This Row],[Discount]]) -> 357.2343
A8: SALE6 | B8: 45850 | C8: CUST1016 | D8: =VLOOKUP(E8,Product_Dim!A:B,2,FALSE) -> Premium Blanket Throw | E8: PROD56 | F8: STORE4 | G8: 2 | H8: 785.31 | I8: 0.15 | J8: PayPal | K8: =sale_tab[[#This Row],[Quantity]]*sale_tab[[#This Row],[Unit_Price]]*(1-sale_tab[[#This Row],[Discount]]) -> 1335.027
A9: SALE7 | B9: 45248 | C9: CUST1152 | D9: =VLOOKUP(E9,Product_Dim!A:B,2,FALSE) -> Kitchen Storage Rack | E9: PROD70 | F9: STORE8 | G9: 4 | H9: 342.39 | I9: 0.23 | J9: PayPal | K9: =sale_tab[[#This Row],[Quantity]]*sale_tab[[#This Row],[Unit_Price]]*(1-sale_tab[[#This Row],[Discount]]) -> 1054.5612
A10: SALE8 | B10: 45781 | C10: CUST1187 | D10: =VLOOKUP(E10,Product_Dim!A:B,2,FALSE) -> Stainless Steel Cookware Set | E10: PROD99 | F10: STORE5 | G10: 2.4796175 | H10: 448.25 | I10: 0.07 | J10: PayPal | K10: =sale_tab[[#This Row],[Quantity]]*sale_tab[[#This Row],[Unit_Price]]*(1-sale_tab[[#This Row],[Discount]]) -> 1033.6844
A11: SALE9 | B11: 45869 | C11: CUST1464 | D11: =VLOOKUP(E11,Product_Dim!A:B,2,FALSE) -> Modern Wall Clock | E11: PROD33 | F11: STORE0 | G11: 2 | H11: 873.17 | I11: 0.23 | J11: PayPal | K11: =sale_tab[[#This Row],[Quantity]]*sale_tab[[#This Row],[Unit_Price]]*(1-sale_tab[[#This Row],[Discount]]) -> 1344.6818
A12: SALE10 | B12: 45335 | C12: CUST1065 | D12: =VLOOKUP(E12,Product_Dim!A:B,2,FALSE) -> Foldable Camping Chair | E12: PROD24 | F12: STORE14 | G12: 1 | H12: 278.63 | I12: 0.07 | J12: Credit Card | K12: =sale_tab[[#This Row],[Quantity]]*sale_tab[[#This Row],[Unit_Price]]*(1-sale_tab[[#This Row],[Discount]]) -> 259.1259
A13: SALE11 | B13: 45801 | C13: CUST1320 | D13: =VLOOKUP(E13,Product_Dim!A:B,2,FALSE) -> Portable Power Bank | E13: PROD39 | F13: STORE1 | G13: 4 | H13: 286.92 | I13: 0.17 | J13: Credit Card | K13: =sale_tab[[#This Row],[Quantity]]*sale_tab[[#This Row],[Unit_Price]]*(1-sale_tab[[#This Row],[Discount]]) -> 952.5744
A14: SALE12 | B14: 45528 | C14: CUST1237 | D14: =VLOOKUP(E14,Product_Dim!A:B,2,FALSE) -> Sports Wrist Sweatbands | E14: PROD88 | F14: STORE4 | G14: 4 | H14: 644.58 | I14: 0.01 | J14: Credit Card | K14: =sale_tab[[#This Row],[Quantity]]*sale_tab[[#This Row],[Unit_Price]]*(1-sale_tab[[#This Row],[Discount]]) -> 2552.5368
... A20: SALE18 | B20: 45517 | C20: CUST1094 | D20: =VLOOKUP(E20,Product_Dim!A:B,2,FALSE) -> Portable Power Bank | E20: PROD39 | F20: STORE4 | G20: 2 | H20: 559.23 | I20: 0.25 | J20: COD | K20: =sale_tab[[#This Row],[Quantity]]*sale_tab[[#This Row],[Unit_Price]]*(1-sale_tab[[#This Row],[Discount]]) -> 838.845
A21: SALE19 | B21: 45369 | C21: CUST1239 | D21: =VLOOKUP(E21,Product_Dim!A:B,2,FALSE) -> Luxury Perfume Spray | E21: PROD60 | F21: STORE13 | G21: 4 | I21: 0.04 | J21: COD | K21: =sale_tab[[#This Row],[Quantity]]*sale_tab[[#This Row],[Unit_Price]]*(1-sale_tab[[#This Row],[Discount]]) -> 0
A22: SALE20 | B22: 45843 | C22: CUST1144 | D22: =VLOOKUP(E22,Product_Dim!A:B,2,FALSE) -> Professional Jump Rope | E22: PROD72 | F22: STORE17 | G22: 3 | H22: 986.04 | I22: 0.27 | J22: COD | K22: =sale_tab[[#This Row],[Quantity]]*sale_tab[[#This Row],[Unit_Price]]*(1-sale_tab[[#This Row],[Discount]]) -> 2159.4276
A23: SALE21 | B23: 45447 | C23: CUST1396 | D23: =VLOOKUP(E23,Product_Dim!A:B,2,FALSE) -> USB External Hard Drive | E23: PROD43 | F23: STORE18 | G23: 1 | H23: 589.56 | I23: 0.22 | J23: Credit Card | K23: =sale_tab[[#This Row],[Quantity]]*sale_tab[[#This Row],[Unit_Price]]*(1-sale_tab[[#This Row],[Discount]]) -> 459.8568
A24: SALE22 | B24: 45394 | C24: CUST1476 | D24: =VLOOKUP(E24,Product_Dim!A:B,2,FALSE) -> Men's Sports Shorts | E24: PROD69 | F24: STORE10 | G24: 3 | H24: 979.42 | I24: 0.03 | J24: PayPal | K24: =sale_tab[[#This Row],[Quantity]]*sale_tab[[#This Row],[Unit_Price]]*(1-sale_tab[[#This Row],[Discount]]) -> 2850.1122
A25: SALE23 | B25: 45466 | C25: CUST1368 | D25: =VLOOKUP(E25,Product_Dim!A:B,2,FALSE) -> Hair Strengthening Shampoo | E25: PROD12 | F25: STORE8 | G25: 1 | H25: 719.28 | I25: 0.08 | J25: Credit Card | K25: =sale_tab[[#This Row],[Quantity]]*sale_tab[[#This Row],[Unit_Price]]*(1-sale_tab[[#This Row],[Discount]]) -> 661.7376
A26: SALE24 | B26: 45908 | C26: CUST1186 | D26: =VLOOKUP(E26,Product_Dim!A:B,2,FALSE) -> Smart LED Light Strip | E26: PROD67 | F26: STORE6 | G26: 3 | H26: 77.6 | I26: 0.07 | J26: Credit Card | K26: =sale_tab[[#This Row],[Quantity]]*sale_tab[[#This Row],[Unit_Price]]*(1-sale_tab[[#This Row],[Discount]]) -> 216.504
A27: SALE25 | B27: 45552 | C27: CUST1381 | D27: =VLOOKUP(E27,Product_Dim!A:B,2,FALSE) -> Men's Leather Belt | E27: PROD5 | F27: STORE3 | G27: 4 | H27: 852.71 | I27: 0.14 | J27: PayPal | K27: =sale_tab[[#This Row],[Quantity]]*sale_tab[[#This Row],[Unit_Price]]*(1-sale_tab[[#This Row],[Discount]]) -> 2933.3224
A28: SALE26 | B28: 45294 | C28: CUST1213 | D28: =VLOOKUP(E28,Product_Dim!A:B,2,FALSE) -> Portable Bluetooth Speaker | E28: PROD98 | F28: STORE8 | G28: 4 | H28: 156.16 | J28: Credit Card | K28: =sale_tab[[#This Row],[Quantity]]*sale_tab[[#This Row],[Unit_Price]]*(1-sale_tab[[#This Row],[Discount]]) -> 624.64
A29: SALE27 | B29: 45710 | C29: CUST1200 | D29: =VLOOKUP(E29,Product_Dim!A:B,2,FALSE) -> WiFi Mesh Router | E29: PROD77 | F29: STORE8 | G29: 3 | H29: 815.49 | I29: 0.17 | J29: Credit Card | K29: =sale_tab[[#This Row],[Quantity]]*sale_tab[[#This Row],[Unit_Price]]*(1-sale_tab[[#This Row],[Discount]]) -> 2030.5701
A30: SALE28 | B30: 45923 | C30: CUST1148 | D30: =VLOOKUP(E30,Product_Dim!A:B,2,FALSE) -> USB-C Fast Charger | E30: PROD13 | F30: STORE2 | G30: 2 | H30: 74.21 | I30: 0.11 | J30: PayPal | K30: =sale_tab[[#This Row],[Quantity]]*sale_tab[[#This Row],[Unit_Price]]*(1-sale_tab[[#This Row],[Discount]]) -> 132.0938
A31: SALE29 | B31: 45302 | C31: CUST1348 | D31: =VLOOKUP(E31,Product_Dim!A:B,2,FALSE) -> Stainless Steel Cookware Set | E31: PROD99 | F31: STORE3 | G31: 2.4776423 | H31: 451.67 | I31: 0.15 | J31: Credit Card | K31: =sale_tab[[#This Row],[Quantity]]*sale_tab[[#This Row],[Unit_Price]]*(1-sale_tab[[#This Row],[Discount]]) -> 951.21518
A32: SALE30 | B32: 45217 | C32: CUST1028 | D32: =VLOOKUP(E32,Product_Dim!A:B,2,FALSE) -> Men's Leather Belt | E32: PROD5 | F32: STORE19 | G32: 1 | H32: 429.38 | I32: 0.13 | J32: PayPal | K32: =sale_tab[[#This Row],[Quantity]]*sale_tab[[#This Row],[Unit_Price]]*(1-sale_tab[[#This Row],[Discount]]) -> 373.5606
A33: SALE31 | B33: 45593 | C33: CUST1412 | D33: =VLOOKUP(E33,Product_Dim!A:B,2,FALSE) -> Men's Track Pants | E33: PROD53 | F33: STORE12 | G33: 2 | H33: 148.96 | I33: 0.03 | J33: COD | K33: =sale_tab[[#This Row],[Quantity]]*sale_tab[[#This Row],[Unit_Price]]*(1-sale_tab[[#This Row],[Discount]]) -> 288.9824
A34: SALE32 | B34: 45597 | C34: CUST1398 | D34: =VLOOKUP(E34,Product_Dim!A:B,2,FALSE) -> Women's Ankle Boots | E34: PROD75 | F34: STORE8 | G34: 4 | H34: 313.83 | I34: 0.08 | J34: Credit Card | K34: =sale_tab[[#This Row],[Quantity]]*sale_tab[[#This Row],[Unit_Price]]*(1-sale_tab[[#This Row],[Discount]]) -> 1154.8944
A35: SALE33 | B35: 45620 | C35: CUST1453 | D35: =VLOOKUP(E35,Product_Dim!A:B,2,FALSE) -> Hair Strengthening Shampoo | E35: PROD12 | F35: STORE6 | G35: 2 | H35: 717.31 | I35: 0.15 | J35: Credit Card | K35: =sale_tab[[#This Row],[Quantity]]*sale_tab[[#This Row],[Unit_Price]]*(1-sale_tab[[#This Row],[Discount]]) -> 1219.427
A36: SALE34 | B36: 45215 | C36: CUST1344 | D36: =VLOOKUP(E36,Product_Dim!A:B,2,FALSE) -> Decorative Lamp Shade | E36: PROD79 | F36: STORE1 | G36: 2.4781059 | H36: 873.22 | I36: 0.18 | J36: Credit Card | K36: =sale_tab[[#This Row],[Quantity]]*sale_tab[[#This Row],[Unit_Price]]*(1-sale_tab[[#This Row],[Discount]]) -> 1774.4239
A37: SALE35 | B37: 45878 | C37: CUST1218 | D37: =VLOOKUP(E37,Product_Dim!A:B,2,FALSE) -> Beard Grooming Kit | E37: PROD16 | F37: STORE3 | G37: 4 | H37: 109.36 | I37: 0.19 | J37: COD | K37: =sale_tab[[#This Row],[Quantity]]*sale_tab[[#This Row],[Unit_Price]]*(1-sale_tab[[#This Row],[Discount]]) -> 354.3264
A38: SALE36 | B38: 45635 | C38: CUST1086 | D38: =VLOOKUP(E38,Product_Dim!A:B,2,FALSE) -> Men's Leather Belt | E38: PROD5 | F38: STORE7 | G38: 3 | H38: 559.52 | I38: 0.16 | J38: PayPal | K38: =sale_tab[[#This Row],[Quantity]]*sale_tab[[#This Row],[Unit_Price]]*(1-sale_tab[[#This Row],[Discount]]) -> 1409.9904
A39: SALE37 | B39: 45329 | C39: CUST1492 | D39: =VLOOKUP(E39,Product_Dim!A:B,2,FALSE) -> Ceramic Kitchen Bowl Set | E39: PROD10 | F39: STORE17 | G39: 3 | H39: 121.76 | I39: 0.27 | J39: PayPal | K39: =sale_tab[[#This Row],[Quantity]]*sale_tab[[#This Row],[Unit_Price]]*(1-sale_tab[[#This Row],[Discount]]) -> 266.6544
A40: SALE38 | B40: 45378 | C40: CUST1189 | D40: =VLOOKUP(E40,Product_Dim!A:B,2,FALSE) -> Modern Wall Clock | E40: PROD33 | F40: STORE13 | G40: 4 | H40: 735.32 | I40: 0.06 | J40: COD | K40: =sale_tab[[#This Row],[Quantity]]*sale_tab[[#This Row],[Unit_Price]]*(1-sale_tab[[#This Row],[Discount]]) -> 2764.8032
... A53: SALE51 | B53: 45689 | C53: CUST1142 | D53: =VLOOKUP(E53,Product_Dim!A:B,2,FALSE) -> Men's Sports Shorts | E53: PROD69 | F53: STORE7 | G53: 3 | H53: 76.57 | I53: 0.26 | J53: Credit Card | K53: =sale_tab[[#This Row],[Quantity]]*sale_tab[[#This Row],[Unit_Price]]*(1-sale_tab[[#This Row],[Discount]]) -> 169.9854
A54: SALE52 | B54: 45894 | C54: CUST1148 | D54: =VLOOKUP(E54,Product_Dim!A:B,2,FALSE) -> Face Foundation Kit | E54: PROD89 | F54: STORE6 | G54: 3 | J54: Credit Card | K54: =sale_tab[[#This Row],[Quantity]]*sale_tab[[#This Row],[Unit_Price]]*(1-sale_tab[[#This Row],[Discount]]) -> 0
A55: SALE53 | B55: 45677 | C55: CUST1324 | D55: =VLOOKUP(E55,Product_Dim!A:B,2,FALSE) -> Outdoor Sports Water Bottle | E55: PROD20 | F55: STORE8 | G55: 1 | H55: 900.35 | I55: 0.13 | J55: COD | K55: =sale_tab[[#This Row],[Quantity]]*sale_tab[[#This Row],[Unit_Price]]*(1-sale_tab[[#This Row],[Discount]]) -> 783.3045
A56: SALE54 | B56: 45706 | C56: CUST1095 | D56: =VLOOKUP(E56,Product_Dim!A:B,2,FALSE) -> Noise-Canceling Headphones | E56: PROD40 | F56: STORE10 | G56: 4 | H56: 428.09 | I56: 0.07 | J56: Credit Card | K56: =sale_tab[[#This Row],[Quantity]]*sale_tab[[#This Row],[Unit_Price]]*(1-sale_tab[[#This Row],[Discount]]) -> 1592.4948
A57: SALE55 | B57: 45589 | C57: CUST1416 | D57: =VLOOKUP(E57,Product_Dim!A:B,2,FALSE) -> Men's Roll-On Perfume | E57: PROD49 | F57: STORE11 | G57: 2 | H57: 559.71 | I57: 0.3 | J57: COD | K57: =sale_tab[[#This Row],[Quantity]]*sale_tab[[#This Row],[Unit_Price]]*(1-sale_tab[[#This Row],[Discount]]) -> 783.594
...

Sheet data analysis tool
A1: Descriptive Analysis | B1: Total Price
A3: Mean | B3: 1087.629 | D3: Mean | J3: Range
A4: Standard Error | B4: 18.356936 | D4: Average value of data is consider as Mean 1087.62 | J4: Difference between Max and Min 3889.7838
A5: Median | B5: 868.7182 | D5: Standard Error | J5: Minimum
A6: Mode | B6: #N/A | D6: Accuracy of Mean 18.35 | J6: Minimum Value in the Data set 18.459
A7: Standard Deviation | B7: 820.12576 | D7: Median | J7: Maximum
A8: Sample Variance | B8: 672606.27 | D8: Middle Value of DataSet 868.7182 | J8: Maximum Value in the Data Set is 3889.7838
A9: Kurtosis | B9: 0.041826531 | D9: Mode
A10: Skewness | B10: 0.87824016 | D10: Most Repeated Value
A11: Range | B11: 3889.7838 | D11: Standard Deviation
A12: Minimum | B12: 18.459 | D12: Data Varriance is close to the mean so consistent data
A13: Maximum | B13: 3908.2428 | D13: Sample Variancee
A14: Sum | B14: 2170907.5 | D14: Spread Mesurements, how long data will spread here, data points are widely spread
A15: Count | B15: 1996 | D15: kurtosis
D16: kurtosis value is Positive ,greater than zero, Slightly Leptokurtic
D17: Distribution is Slightly more Peaked than a Normal Distritions
D18: Skewness
D19: skewness value is positive so positively Skewed Distribution
D20: Tail is extends towards the Right Side

Sheet monthly anaysis
A3: YEAR | B3: Total Price | G3: Monthly Sales Analysis
A4: 2023 | B4: 223439.03
A5: 2024 | B5: 294374.01
A6: 2025 | B6: 38467.816 | K6: Descriptive Analysis
A7: Grand Total | B7: 556280.85 | K7: *2024 is highest sale
K8: *2025 is second high sale
K10: Diagnosis
K11: In 2013 Qtr1Qtr2,Qtr3 there is no sales
K12: in 202 Qtr3 Sale is High

Sheet store vs yearwise sale
H2: Store vs year wise sale
A3: Store Id | B3: Unit Price | C3: Total Price
A4: STORE0 | B4: 93 | C4: 85138.555
A5: STORE1 | B5: 94 | C5: 100686.91 | E5: Descriptive Analysis
A6: STORE10 | B6: 97 | C6: 109791.72
A7: STORE11 | B7: 88 | C7: 93048.141 | E7: *STORE8 has highest unit and Sale
A8: STORE12 | B8: 100 | C8: 116829.22 | E8: * Store19 has second Lowest sale
A9: STORE13 | B9: 95 | C9: 114592.78 | E9: * STORE3 has second highest sale
A10: STORE14 | B10: 95 | C10: 106248.28
A11: STORE15 | B11: 95 | C11: 99679.086 | E11: diagnosis Analysis
A12: STORE16 | B12: 106 | C12: 111704.94 | E12: * In 2024 has highest sale
A13: STORE17 | B13: 110 | C13: 121851.21 | E13: * In 2023 has low sale
A14: STORE18 | B14: 105 | C14: 105447.29
A15: STORE19 | B15: 94 | C15: 94225.723
A16: STORE2 | B16: 92 | C16: 99081.61
A17: STORE3 | B17: 114 | C17: 124427.37
A18: STORE4 | B18: 102 | C18: 118814.12
A19: STORE5 | B19: 83 | C19: 81126.656
A20: STORE6 | B20: 106 | C20: 115589.73
A21: STORE7 | B21: 108 | C21: 108420.73
A22: STORE8 | B22: 127 | C22: 157954.38
A23: STORE9 | B23: 96 | C23: 109666.21
A24: Grand Total | B24: 2000 | C24: 2174324.7

Sheet Customer Loyality analysis
A3: Loylity vs Age Category | B3: Quantity | C3: Total Sale | F3: Customer Loyality Analysis
A4: Adults Age | B4: 30 | C4: 35953.151
A5: Middle age | B5: 67 | C5: 70232.992
A6: Senior Citizen | B6: 14 | C6: 12242.252
A7: Teenage | B7: 5 | C7: 2296.0085
A8: Young People | B8: 29 | C8: 28821.739
A9: Grand Total | B9: 145 | C9: 149546.14

Sheet sales by store vs region
G2: Sales By Store and Region
A3: Store Type and Region | B3: Total Price
A4: East | B4: 301755.38
A5: North | B5: 322217.21 | M5: Descriptive Analysis
A6: South | B6: 109666.21 | M6: * North Region has high Revenue
A7: West | B7: 111704.94 | M7: * South Region is second highest
A8: Grand Total | B8: 845343.75
M9: Diagnosis Analysis
M10: * Online Store has high sale
M11: * Outlet store has low sale

Sheet Age vs Purchase
G2: Age Category Vs Year
A3: Total Price | B3: Column Labels
B4: 2023 | C4: 2024 | D4: 2025 | E4: Grand Total
A7: Row Labels
A8: Adults Age | B8: 39966.116 | C8: 192123.6 | D8: 179076.96 | E8: 411166.67
A9: Middle age | B9: 116041.56 | C9: 506072.8 | D9: 352318.56 | E9: 974432.92
A10: Senior Citizen | B10: 16849.071 | C10: 95251.297 | D10: 63167.5 | E10: 175267.87
A11: Teenage | B11: 4937.2869 | C11: 45706.101 | D11: 59695.208 | E11: 110338.6
A12: Young People | B12: 44971.121 | C12: 239034.74 | D12: 187689.41 | E12: 471695.27
A13: (blank) | B13: 673.875 | C13: 11770.785 | D13: 13815.009 | E13: 26259.669
A14: Grand Total | B14: 223439.03 | C14: 1089959.3 | D14: 855762.65 | E14: 2169161
A16: descripive Analysis
A17: * Middle age people purchase more
A18: * Young age People second Most
A20: Diagnosis Analysis
A21: * purchase high in 2024
A22: * second highest is 2025

Sheet DASHBOARD
G1: ECOMMERCE SALES ANALYSIS DASHBOARDS
Q2: Overall sales 21,69,369 Avg Sale 1085
